<?xml version="1.0" ?>
<robot name="robot_description" xmlns:xacro="http://www.ros.org/wiki/xacro">

  <xacro:property name="cameraSize" value="0.05"/>
  <xacro:property name="cameraMass" value="0.1"/>

  <xacro:include filename="$(find medbot)/urdf/provanew.gazebo" />
  <xacro:include filename="$(find medbot)/urdf/materials.xacro" />

  <!--Dummy base link-->
  <link name="chassis">
  </link>
  

  <joint name="base_link_to_base" type="fixed">
    <parent link="chassis"/>
    <child link="base_link" />
    <origin rpy="0.0 0 0" xyz="0.15 0 0"/>
  </joint>
  
  <!--Base Link-->
  <link name='base_link'>
    <inertial>
      <mass value="9.8129" />
      <origin xyz="-0 0 0" rpy="0 0 0"/>
      <inertia
        ixx="1.0087" ixy="-6.05459e-06" ixz="-0.0112309" iyy="11.3554" iyz="-0.000118317" izz="0.684012"/>
    </inertial>

    <collision name='collision'>
      <origin xyz="0 0 0" rpy="0 0 0" />
      <geometry>
        <mesh filename="package://medbot/meshes/base_link.stl" scale="0.001 0.001 0.001"/>
      </geometry>
      <surface>
        <friction>
          <ode>
            <mu>0</mu>
            <mu2>0</mu2>
            <slip1>1.0</slip1>
            <slip2>1.0</slip2>
          </ode>
        </friction>
      </surface>
    </collision>

    <visual name='base_link_visual'>
      <origin xyz="-0 0 0" rpy="0 0 0" />
      <geometry>
        <mesh filename="package://medbot/meshes/base_link.stl" scale="0.001 0.001 0.001"/>
      </geometry>
    </visual>
  </link>

  <!--Left Standard Fixed Wheel-->
  <link name="left_wheel">
    <collision name="collision">
      <origin xyz="0.15 -0.201 -0.12" rpy="-0 0 0" />
      <geometry>
        <mesh filename="package://medbot/meshes/left_wheel_1.stl" scale="0.001 0.001 0.001"/>
      </geometry>
    </collision>
    <visual name="left_wheel_visual">
      <origin xyz="0.15 -0.201 -0.12" rpy="0 0 0" />
      <geometry>
      <mesh filename="package://medbot/meshes/left_wheel_1.stl" scale="0.001 0.001 0.001"/>
      </geometry>
    </visual>
    <inertial>
      <origin xyz="2.7755575615628914e-17 0.024999999999999994 0.0" rpy="0 0 0"/>
      <mass value="2.1036104408437253" />
      <inertia
        ixx="0.008011" iyy="0.015146" izz="0.008011" ixy="0.0" iyz="-0.0" ixz="0.0"/>
    </inertial>
  </link>

  <joint type="continuous" name="left_wheel_hinge">
    <origin xyz="-0.15 0.201 0.12" rpy="0 0 0"/>
    <parent link="base_link"/>
    <child link="left_wheel"/>
    <axis xyz="0.0 1.0 0.0"/>
    <limit effort="10000" velocity="1000"/>
    <joint_properties damping="1.0" friction="1.0"/>
  </joint>

  <!--Right Standard Fixed Wheel-->
  <link name="right_wheel">
    <collision name="collision">
      <origin xyz="0.15 0.201 -0.12" rpy="0 -0 0" />
      <geometry>
        <mesh filename="package://medbot/meshes/right_wheel_1.stl" scale="0.001 0.001 0.001"/>
      </geometry>
    </collision>
    <visual name="right_wheel_visual">
      <origin xyz="0.15 0.201 -0.12" rpy="0 -0 0" />
      <geometry>
        <mesh filename="package://medbot/meshes/right_wheel_1.stl" scale="0.001 0.001 0.001"/>
      </geometry>
    </visual>
    <inertial>
      <origin xyz="0.0 -0.02500000000000005 0.0" rpy="0 0 0"/>
      <mass value="2.1036104408437253" />
      <inertia
        ixx="0.008011" iyy="0.015146" izz="0.008011" ixy="0.0" iyz="-0.0" ixz="0.0"/>
    </inertial>
  </link>

  <joint type="continuous" name="right_wheel_hinge">
    <origin xyz="-0.15 -0.201 0.12" rpy="0 0 0"/>
    <parent link="base_link"/>
    <child link="right_wheel"/>
    <axis xyz="0.0 1.0 0.0"/>
    <limit effort="10000" velocity="1000"/>
    <joint_properties damping="1.0" friction="1.0"/>
  </joint>
  
  <link name="camera">
    <collision>
      <origin xyz="0 0 0" rpy="0 0 0"/>
      <geometry>
        <box size="${cameraSize} ${cameraSize} ${cameraSize}"/>
      </geometry>
    </collision>

    <visual>
      <origin xyz="0 0 0" rpy="0 0 0"/>
      <geometry>
        <box size="${cameraSize} ${cameraSize} ${cameraSize}"/>
      </geometry>
      <material name="green"/>
    </visual>

    <inertial>
      <mass value="${cameraMass}" />
      <origin xyz="0 0 0" rpy="0 0 0"/>
      <box_inertia m="${cameraMass}" x="${cameraSize}" y="${cameraSize}" z="${cameraSize}" />
      <inertia ixx="1e-6" ixy="0" ixz="0" iyy="1e-6" iyz="0" izz="1e-6" />
    </inertial>
  </link>
  

  <!-- Hokuyo Laser -->
  <link name="hokuyo">
    <collision>
      <origin xyz="0 0 0" rpy="0 0 0"/>
      <geometry>
    <box size="0.1 0.1 0.1"/>
      </geometry>
    </collision>

    <visual>
      <origin xyz="0 0 0" rpy="0 0 0"/>
      <geometry>
        <mesh filename="package://medbot/meshes/hokuyo.dae"/>
      </geometry>
    </visual>

    <inertial>
      <mass value="1e-5" />
      <origin xyz="0 0 0" rpy="0 0 0"/>
      <inertia ixx="1e-6" ixy="0" ixz="0" iyy="1e-6" iyz="0" izz="1e-6" />
    </inertial>
  </link>

  <joint name="camera_joint" type="fixed">
    <axis xyz="0 1 0" />
    <origin xyz="0.3 0 0.2" rpy="0 0 0"/>
    <parent link="base_link"/>
    <child link="camera"/>
  </joint>

  <joint name="hokuyo_joint" type="fixed">
    <axis xyz="0 1 0" />
    <origin xyz=".25 0 .35" rpy="0 0 0"/>
    <parent link="base_link"/>
    <child link="hokuyo"/>
  </joint>
</robot>
